Workbook

Sheet Satışlar
A1: 2024 Satış Raporu — İĞÜŞÖÇ
A2: Ürün | B2: Şehir | C2: Adet | D2: Fiyat | E2: Tarih | F2: Tutar | G2: KDV | H2: Durum | J2: Döndürülmüş ve kaydırılmış uzun başlık metni
A3: Çay | B3: İstanbul | C3: 1 | D3: 5 | E3: =DATE(2024,1,1) -> 45292 | F3: =C3*D3 -> 5 | G3: =ROUND(F3*0.2,2) -> 1 | H3: =IF(F3>500,"Yüksek",IF(F3>100,"Orta","Düşük")) -> Düşük
A4: Şeker | B4: Ankara | C4: 8 | D4: 7.75 | E4: =DATE(2024,2,2) -> 45324 | F4: =C4*D4 -> 62 | G4: =ROUND(F4*0.2,2) -> 12.4 | H4: =IF(F4>500,"Yüksek",IF(F4>100,"Orta","Düşük")) -> Düşük
A5: Ğofret | B5: İzmir | C5: 15 | D5: 10.5 | E5: =DATE(2024,3,3) -> 45354 | F5: =C5*D5 -> 157.5 | G5: =ROUND(F5*0.2,2) -> 31.5 | H5: =IF(F5>500,"Yüksek",IF(F5>100,"Orta","Düşük")) -> Orta
A6: Kahve | B6: Bursa | C6: 22 | D6: 13.25 | E6: =DATE(2024,4,4) -> 45386 | F6: =C6*D6 -> 291.5 | G6: =ROUND(F6*0.2,2) -> 58.3 | H6: =IF(F6>500,"Yüksek",IF(F6>100,"Orta","Düşük")) -> Orta
A7: Süt | B7: Çanakkale | C7: 29 | D7: 16 | E7: =DATE(2024,5,5) -> 45417 | F7: =C7*D7 -> 464 | G7: =ROUND(F7*0.2,2) -> 92.8 | H7: =IF(F7>500,"Yüksek",IF(F7>100,"Orta","Düşük")) -> Orta
A8: Peynir | B8: İstanbul | C8: 36 | D8: 18.75 | E8: =DATE(2024,6,6) -> 45449 | F8: =C8*D8 -> 675 | G8: =ROUND(F8*0.2,2) -> 135 | H8: =IF(F8>500,"Yüksek",IF(F8>100,"Orta","Düşük")) -> Yüksek
A9: Zeytin | B9: Ankara | C9: 43 | D9: 21.5 | E9: =DATE(2024,7,7) -> 45480 | F9: =C9*D9 -> 924.5 | G9: =ROUND(F9*0.2,2) -> 184.9 | H9: =IF(F9>500,"Yüksek",IF(F9>100,"Orta","Düşük")) -> Yüksek
A10: Ekmek | B10: İzmir | C10: 50 | D10: 24.25 | E10: =DATE(2024,8,8) -> 45512 | F10: =C10*D10 -> 1212.5 | G10: =ROUND(F10*0.2,2) -> 242.5 | H10: =IF(F10>500,"Yüksek",IF(F10>100,"Orta","Düşük")) -> Yüksek
A11: Bal | B11: Bursa | C11: 7 | D11: 27 | E11: =DATE(2024,9,9) -> 45544 | F11: =C11*D11 -> 189 | G11: =ROUND(F11*0.2,2) -> 37.8 | H11: =IF(F11>500,"Yüksek",IF(F11>100,"Orta","Düşük")) -> Orta
A12: Un | B12: Çanakkale | C12: 14 | D12: 29.75 | E12: =DATE(2024,10,10) -> 45575 | F12: =C12*D12 -> 416.5 | G12: =ROUND(F12*0.2,2) -> 83.3 | H12: =IF(F12>500,"Yüksek",IF(F12>100,"Orta","Düşük")) -> Orta
A13: Çay | B13: İstanbul | C13: 21 | D13: 32.5 | E13: =DATE(2024,11,11) -> 45607 | F13: =C13*D13 -> 682.5 | G13: =ROUND(F13*0.2,2) -> 136.5 | H13: =IF(F13>500,"Yüksek",IF(F13>100,"Orta","Düşük")) -> Yüksek
A14: Şeker | B14: Ankara | C14: 28 | D14: 35.25 | E14: =DATE(2024,12,12) -> 45638 | F14: =C14*D14 -> 987 | G14: =ROUND(F14*0.2,2) -> 197.4 | H14: =IF(F14>500,"Yüksek",IF(F14>100,"Orta","Düşük")) -> Yüksek
A15: Ğofret | B15: İzmir | C15: 35 | D15: 38 | E15: =DATE(2024,1,13) -> 45304 | F15: =C15*D15 -> 1330 | G15: =ROUND(F15*0.2,2) -> 266 | H15: =IF(F15>500,"Yüksek",IF(F15>100,"Orta","Düşük")) -> Yüksek
A16: Kahve | B16: Bursa | C16: 42 | D16: 5 | E16: =DATE(2024,2,14) -> 45336 | F16: =C16*D16 -> 210 | G16: =ROUND(F16*0.2,2) -> 42 | H16: =IF(F16>500,"Yüksek",IF(F16>100,"Orta","Düşük")) -> Orta
A17: Süt | B17: Çanakkale | C17: 49 | D17: 7.75 | E17: =DATE(2024,3,15) -> 45366 | F17: =C17*D17 -> 379.75 | G17: =ROUND(F17*0.2,2) -> 75.95 | H17: =IF(F17>500,"Yüksek",IF(F17>100,"Orta","Düşük")) -> Orta
A18: Peynir | B18: İstanbul | C18: 6 | D18: 10.5 | E18: =DATE(2024,4,16) -> 45398 | F18: =C18*D18 -> 63 | G18: =ROUND(F18*0.2,2) -> 12.6 | H18: =IF(F18>500,"Yüksek",IF(F18>100,"Orta","Düşük")) -> Düşük
A19: Zeytin | B19: Ankara | C19: 13 | D19: 13.25 | E19: =DATE(2024,5,17) -> 45429 | F19: =C19*D19 -> 172.25 | G19: =ROUND(F19*0.2,2) -> 34.45 | H19: =IF(F19>500,"Yüksek",IF(F19>100,"Orta","Düşük")) -> Orta
A20: Ekmek | B20: İzmir | C20: 20 | D20: 16 | E20: =DATE(2024,6,18) -> 45461 | F20: =C20*D20 -> 320 | G20: =ROUND(F20*0.2,2) -> 64 | H20: =IF(F20>500,"Yüksek",IF(F20>100,"Orta","Düşük")) -> Orta
A21: Bal | B21: Bursa | C21: 27 | D21: 18.75 | E21: =DATE(2024,7,19) -> 45492 | F21: =C21*D21 -> 506.25 | G21: =ROUND(F21*0.2,2) -> 101.25 | H21: =IF(F21>500,"Yüksek",IF(F21>100,"Orta","Düşük")) -> Yüksek
A22: Un | B22: Çanakkale | C22: 34 | D22: 21.5 | E22: =DATE(2024,8,20) -> 45524 | F22: =C22*D22 -> 731 | G22: =ROUND(F22*0.2,2) -> 146.2 | H22: =IF(F22>500,"Yüksek",IF(F22>100,"Orta","Düşük")) -> Yüksek
A23: Çay | B23: İstanbul | C23: 41 | D23: 24.25 | E23: =DATE(2024,9,21) -> 45556 | F23: =C23*D23 -> 994.25 | G23: =ROUND(F23*0.2,2) -> 198.85 | H23: =IF(F23>500,"Yüksek",IF(F23>100,"Orta","Düşük")) -> Yüksek
A24: Şeker | B24: Ankara | C24: 48 | D24: 27 | E24: =DATE(2024,10,22) -> 45587 | F24: =C24*D24 -> 1296 | G24: =ROUND(F24*0.2,2) -> 259.2 | H24: =IF(F24>500,"Yüksek",IF(F24>100,"Orta","Düşük")) -> Yüksek
A25: Ğofret | B25: İzmir | C25: 5 | D25: 29.75 | E25: =DATE(2024,11,23) -> 45619 | F25: =C25*D25 -> 148.75 | G25: =ROUND(F25*0.2,2) -> 29.75 | H25: =IF(F25>500,"Yüksek",IF(F25>100,"Orta","Düşük")) -> Orta
A26: Kahve | B26: Bursa | C26: 12 | D26: 32.5 | E26: =DATE(2024,12,24) -> 45650 | F26: =C26*D26 -> 390 | G26: =ROUND(F26*0.2,2) -> 78 | H26: =IF(F26>500,"Yüksek",IF(F26>100,"Orta","Düşük")) -> Orta
A27: Süt | B27: Çanakkale | C27: 19 | D27: 35.25 | E27: =DATE(2024,1,25) -> 45316 | F27: =C27*D27 -> 669.75 | G27: =ROUND(F27*0.2,2) -> 133.95 | H27: =IF(F27>500,"Yüksek",IF(F27>100,"Orta","Düşük")) -> Yüksek
A28: Peynir | B28: İstanbul | C28: 26 | D28: 38 | E28: =DATE(2024,2,26) -> 45348 | F28: =C28*D28 -> 988 | G28: =ROUND(F28*0.2,2) -> 197.6 | H28: =IF(F28>500,"Yüksek",IF(F28>100,"Orta","Düşük")) -> Yüksek
A29: Zeytin | B29: Ankara | C29: 33 | D29: 5 | E29: =DATE(2024,3,27) -> 45378 | F29: =C29*D29 -> 165 | G29: =ROUND(F29*0.2,2) -> 33 | H29: =IF(F29>500,"Yüksek",IF(F29>100,"Orta","Düşük")) -> Orta
A30: Ekmek | B30: İzmir | C30: 40 | D30: 7.75 | E30: =DATE(2024,4,28) -> 45410 | F30: =C30*D30 -> 310 | G30: =ROUND(F30*0.2,2) -> 62 | H30: =IF(F30>500,"Yüksek",IF(F30>100,"Orta","Düşük")) -> Orta
A31: Bal | B31: Bursa | C31: 47 | D31: 10.5 | E31: =DATE(2024,5,1) -> 45413 | F31: =C31*D31 -> 493.5 | G31: =ROUND(F31*0.2,2) -> 98.7 | H31: =IF(F31>500,"Yüksek",IF(F31>100,"Orta","Düşük")) -> Orta
A32: Un | B32: Çanakkale | C32: 4 | D32: 13.25 | E32: =DATE(2024,6,2) -> 45445 | F32: =C32*D32 -> 53 | G32: =ROUND(F32*0.2,2) -> 10.6 | H32: =IF(F32>500,"Yüksek",IF(F32>100,"Orta","Düşük")) -> Düşük
A33: Çay | B33: İstanbul | C33: 11 | D33: 16 | E33: =DATE(2024,7,3) -> 45476 | F33: =C33*D33 -> 176 | G33: =ROUND(F33*0.2,2) -> 35.2 | H33: =IF(F33>500,"Yüksek",IF(F33>100,"Orta","Düşük")) -> Orta
A34: Şeker | B34: Ankara | C34: 18 | D34: 18.75 | E34: =DATE(2024,8,4) -> 45508 | F34: =C34*D34 -> 337.5 | G34: =ROUND(F34*0.2,2) -> 67.5 | H34: =IF(F34>500,"Yüksek",IF(F34>100,"Orta","Düşük")) -> Orta
A35: Ğofret | B35: İzmir | C35: 25 | D35: 21.5 | E35: =DATE(2024,9,5) -> 45540 | F35: =C35*D35 -> 537.5 | G35: =ROUND(F35*0.2,2) -> 107.5 | H35: =IF(F35>500,"Yüksek",IF(F35>100,"Orta","Düşük")) -> Yüksek
A36: Kahve | B36: Bursa | C36: 32 | D36: 24.25 | E36: =DATE(2024,10,6) -> 45571 | F36: =C36*D36 -> 776 | G36: =ROUND(F36*0.2,2) -> 155.2 | H36: =IF(F36>500,"Yüksek",IF(F36>100,"Orta","Düşük")) -> Yüksek
A37: Süt | B37: Çanakkale | C37: 39 | D37: 27 | E37: =DATE(2024,11,7) -> 45603 | F37: =C37*D37 -> 1053 | G37: =ROUND(F37*0.2,2) -> 210.6 | H37: =IF(F37>500,"Yüksek",IF(F37>100,"Orta","Düşük")) -> Yüksek
A38: Peynir | B38: İstanbul | C38: 46 | D38: 29.75 | E38: =DATE(2024,12,8) -> 45634 | F38: =C38*D38 -> 1368.5 | G38: =ROUND(F38*0.2,2) -> 273.7 | H38: =IF(F38>500,"Yüksek",IF(F38>100,"Orta","Düşük")) -> Yüksek
A39: Zeytin | B39: Ankara | C39: 3 | D39: 32.5 | E39: =DATE(2024,1,9) -> 45300 | F39: =C39*D39 -> 97.5 | G39: =ROUND(F39*0.2,2) -> 19.5 | H39: =IF(F39>500,"Yüksek",IF(F39>100,"Orta","Düşük")) -> Düşük
A40: Ekmek | B40: İzmir | C40: 10 | D40: 35.25 | E40: =DATE(2024,2,10) -> 45332 | F40: =C40*D40 -> 352.5 | G40: =ROUND(F40*0.2,2) -> 70.5 | H40: =IF(F40>500,"Yüksek",IF(F40>100,"Orta","Düşük")) -> Orta
...

Sheet Özet
A1: Genel toplam | B1: =Satışlar!F53 -> 26430.75
A2: KDV dahil | B2: =B1*1.2 -> 31716.9
A3: Ürün araması | B3: =VLOOKUP("Kahve",Satışlar!A3:F52,6,0) -> 291.5
A4: INDEX/MATCH | B4: =INDEX(Satışlar!B3:B52,MATCH("Süt",Satışlar!A3:A52,0)) -> Çanakkale
A5: Metin | B5: =CONCATENATE("Toplam: ",TEXT(B1,"0.00")) -> Toplam: 26430.75
A6: Büyük harf | B6: =UPPER("istanbul") -> ISTANBUL
A7: Tarih farkı | B7: =DATE(2024,12,31)-DATE(2024,1,1) -> 365
A8: SUMPRODUCT | B8: =SUMPRODUCT(Satışlar!C3:C22,Satışlar!D3:D22) -> 9779.25
A9: IFERROR | B9: =IFERROR(1/0,-1) -> -1
A10: Ortalama (adlı) | B10: =AVERAGE(Fiyatlar) -> 20.895
A11: Yuvarla | B11: =ROUNDUP(PI()*1000,2) -> 3141.6
A12: Mantık | B12: =AND(B1>0,OR(B2<0,TRUE())) -> TRUE
A13: Ay adı | B13: =MONTH(DATE(2024,7,4)) -> 7
A14: Bölü sıfır | B14: =1/0 -> #DIV/0!
A15: Bulunamadı | B15: =VLOOKUP("Yok",Satışlar!A3:F10,2,0) -> #N/A
A16: Std sapma | B16: =STDEV(Satışlar!F3:F52) -> 399.86259
A17: Medyan | B17: =MEDIAN(Satışlar!C3:C52) -> 25.5
A18: Mantıksal değer | B18: =TRUE() -> TRUE

Sheet Zincir
A1: 1 | B1: =A200 -> 631.60179
A2: =A1*1.01+1 -> 2.01 | C2: 3x3 birleşik
A3: =A2*1.01+1 -> 3.0301
A4: =A3*1.01+1 -> 4.060401
A5: =A4*1.01+1 -> 5.101005
A6: =A5*1.01+1 -> 6.1520151 | C6: Dikey birleşik
A7: =A6*1.01+1 -> 7.2135352
A8: =A7*1.01+1 -> 8.2856706
A9: =A8*1.01+1 -> 9.3685273
A10: =A9*1.01+1 -> 10.462213
A11: =A10*1.01+1 -> 11.566835
A12: =A11*1.01+1 -> 12.682503
A13: =A12*1.01+1 -> 13.809328
A14: =A13*1.01+1 -> 14.947421
A15: =A14*1.01+1 -> 16.096896
A16: =A15*1.01+1 -> 17.257864
A17: =A16*1.01+1 -> 18.430443
A18: =A17*1.01+1 -> 19.614748
... A200: =A199*1.01+1 -> 631.60179
